terminate called recursively
terminate called after throwing an instance of 'std::system_error'
terminate called recursively
  what():  Invalid argument
