terminate called after throwing an instance of 'terminate called recursively
std::system_error'
terminate called recursively
  what():  Invalid argument
